Workbook

Sheet Historias de Usuario
B1: Metodologías ágiles: Lista de tareas de la iteración
B2: (Sprint Backlog)
B3: Elaborado por: pmoinformatica.com
H4: Día 1 | K4: Día 2 | N4: Día 3 | Q4: Día 4 | T4: Día 5 | W4: Día 6 | Z4: Día 7 | AC4: Día 8 | AF4: Día 9 | AI4: Día 10 | AL4: Día 11 | AO4: Día 12 | AR4: Día 13 | AU4: Día 14 | AX4: Día 15 | BA4: Día 16 | BD4: Día 17 | BG4: Día 18 | BJ4: Día 19 | BM4: Día 20 | BP4: Total
B5: Identificador (ID) de item de product backlog | C5: Enunciado del item de Product Backlog | D5: Tarea | E5: Dueño / Voluntario | F5: Estatus | G5: Horas estimadas totales | H5: Cons. | I5: Rest. | K5: Cons. | L5: Rest. | N5: Cons. | O5: Rest. | Q5: Cons. | R5: Rest. | T5: Cons. | U5: Rest. | W5: Cons. | X5: Rest. | Z5: Cons. | AA5: Rest. | AC5: Cons. | AD5: Rest. | AF5: Cons. | AG5: Rest. | AI5: Cons. | AJ5: Rest. | AL5: Cons. | AM5: Rest. | AO5: Cons. | AP5: Rest. | AR5: Cons. | AS5: Rest. | AU5: Cons. | AV5: Rest. | AX5: Cons. | AY5: Rest. | BA5: Cons. | BB5: Rest. | BD5: Cons. | BE5: Rest. | BG5: Cons. | BH5: Rest. | BJ5: Cons. | BK5: Rest. | BM5: Cons. | BN5: Rest. | BP5: Cons. | BQ5: Rest.
B6: Sprint 1 · 10/08/2026 al 23/08/2026 · Análisis de problemática y solución N/A | C6: Sin historia de usuario (actividad de documentación) | D6: Analizar la problemática y las necesidades de pacientes y psicólogos | E6: Ambos | F6: Hecho | G6: 12 | H6: 2 | I6: =G6-H6 -> 10 | K6: 2 | L6: =I6-K6 -> 8 | N6: 4 | O6: =L6-N6 -> 4 | Q6: 2 | R6: =O6-Q6 -> 2 | T6: 2 | U6: =R6-T6 -> 0 | X6: =U6-W6 -> 0 | AA6: =X6-Z6 -> 0 | AD6: =AA6-AC6 -> 0 | AG6: =AD6-AF6 -> 0 | AJ6: =AG6-AI6 -> 0 | AM6: =AJ6-AL6 -> 0 | AP6: =AM6-AO6 -> 0 | AS6: =AP6-AR6 -> 0 | AV6: =AS6-AU6 -> 0 | AY6: =AV6-AX6 -> 0 | BB6: =AY6-BA6 -> 0 | BE6: =BB6-BD6 -> 0 | BH6: =BE6-BG6 -> 0 | BK6: =BH6-BJ6 -> 0 | BN6: =BK6-BM6 -> 0 | BP6: =H6+K6+N6+Q6+T6+W6+Z6+AC6+AF6+AI6+AL6+AO6+AR6+AU6+AX6+BA6+BD6+BG6+BJ6+BM6 -> 12 | BQ6: =G6-BP6 -> 0
D7: Definir los requerimientos funcionales y no funcionales | E7: Ambos | F7: Hecho | G7: 10 | I7: =G7-H7 -> 10 | L7: =I7-K7 -> 10 | O7: =L7-N7 -> 10 | R7: =O7-Q7 -> 10 | T7: 2 | U7: =R7-T7 -> 8 | W7: 2 | X7: =U7-W7 -> 6 | Z7: 2 | AA7: =X7-Z7 -> 4 | AC7: 4 | AD7: =AA7-AC7 -> 0 | AG7: =AD7-AF7 -> 0 | AJ7: =AG7-AI7 -> 0 | AM7: =AJ7-AL7 -> 0 | AP7: =AM7-AO7 -> 0 | AS7: =AP7-AR7 -> 0 | AV7: =AS7-AU7 -> 0 | AY7: =AV7-AX7 -> 0 | BB7: =AY7-BA7 -> 0 | BE7: =BB7-BD7 -> 0 | BH7: =BE7-BG7 -> 0 | BK7: =BH7-BJ7 -> 0 | BN7: =BK7-BM7 -> 0 | BP7: =H7+K7+N7+Q7+T7+W7+Z7+AC7+AF7+AI7+AL7+AO7+AR7+AU7+AX7+BA7+BD7+BG7+BJ7+BM7 -> 10 | BQ7: =G7-BP7 -> 0
D8: Definir la propuesta de solución PsicoHábitos-IA | E8: Ambos | F8: Hecho | G8: 6 | I8: =G8-H8 -> 6 | L8: =I8-K8 -> 6 | O8: =L8-N8 -> 6 | R8: =O8-Q8 -> 6 | U8: =R8-T8 -> 6 | X8: =U8-W8 -> 6 | AA8: =X8-Z8 -> 6 | AD8: =AA8-AC8 -> 6 | AF8: 2 | AG8: =AD8-AF8 -> 4 | AI8: 4 | AJ8: =AG8-AI8 -> 0 | AM8: =AJ8-AL8 -> 0 | AP8: =AM8-AO8 -> 0 | AS8: =AP8-AR8 -> 0 | AV8: =AS8-AU8 -> 0 | AY8: =AV8-AX8 -> 0 | BB8: =AY8-BA8 -> 0 | BE8: =BB8-BD8 -> 0 | BH8: =BE8-BG8 -> 0 | BK8: =BH8-BJ8 -> 0 | BN8: =BK8-BM8 -> 0 | BP8: =H8+K8+N8+Q8+T8+W8+Z8+AC8+AF8+AI8+AL8+AO8+AR8+AU8+AX8+BA8+BD8+BG8+BJ8+BM8 -> 6 | BQ8: =G8-BP8 -> 0
B10: Sprint 2 · 24/08/2026 al 06/09/2026 · Planificación y definición del proyecto N/A | C10: Sin historia de usuario (actividad de documentación) | D10: Definir el alcance, la arquitectura y las tecnologías del proyecto | E10: Ambos | F10: Hecho | G10: 12 | H10: 2 | I10: =G10-H10 -> 10 | K10: 3 | L10: =I10-K10 -> 7 | N10: 3 | O10: =L10-N10 -> 4 | Q10: 3 | R10: =O10-Q10 -> 1 | T10: 1 | U10: =R10-T10 -> 0 | X10: =U10-W10 -> 0 | AA10: =X10-Z10 -> 0 | AD10: =AA10-AC10 -> 0 | AG10: =AD10-AF10 -> 0 | AJ10: =AG10-AI10 -> 0 | AM10: =AJ10-AL10 -> 0 | AP10: =AM10-AO10 -> 0 | AS10: =AP10-AR10 -> 0 | AV10: =AS10-AU10 -> 0 | AY10: =AV10-AX10 -> 0 | BB10: =AY10-BA10 -> 0 | BE10: =BB10-BD10 -> 0 | BH10: =BE10-BG10 -> 0 | BK10: =BH10-BJ10 -> 0 | BN10: =BK10-BM10 -> 0 | BP10: =H10+K10+N10+Q10+T10+W10+Z10+AC10+AF10+AI10+AL10+AO10+AR10+AU10+AX10+BA10+BD10+BG10+BJ10+BM10 -> 12 | BQ10: =G10-BP10 -> 0
D11: Planificar los 8 sprints en la Carta Gantt | E11: Ambos | F11: Hecho | G11: 6 | I11: =G11-H11 -> 6 | L11: =I11-K11 -> 6 | O11: =L11-N11 -> 6 | R11: =O11-Q11 -> 6 | T11: 3 | U11: =R11-T11 -> 3 | W11: 2 | X11: =U11-W11 -> 1 | Z11: 1 | AA11: =X11-Z11 -> 0 | AD11: =AA11-AC11 -> 0 | AG11: =AD11-AF11 -> 0 | AJ11: =AG11-AI11 -> 0 | AM11: =AJ11-AL11 -> 0 | AP11: =AM11-AO11 -> 0 | AS11: =AP11-AR11 -> 0 | AV11: =AS11-AU11 -> 0 | AY11: =AV11-AX11 -> 0 | BB11: =AY11-BA11 -> 0 | BE11: =BB11-BD11 -> 0 | BH11: =BE11-BG11 -> 0 | BK11: =BH11-BJ11 -> 0 | BN11: =BK11-BM11 -> 0 | BP11: =H11+K11+N11+Q11+T11+W11+Z11+AC11+AF11+AI11+AL11+AO11+AR11+AU11+AX11+BA11+BD11+BG11+BJ11+BM11 -> 6 | BQ11: =G11-BP11 -> 0
D12: Documentar la definición del proyecto (Guía de la Fase 1) | E12: Ambos | F12: Hecho | G12: 10 | I12: =G12-H12 -> 10 | L12: =I12-K12 -> 10 | O12: =L12-N12 -> 10 | R12: =O12-Q12 -> 10 | U12: =R12-T12 -> 10 | X12: =U12-W12 -> 10 | Z12: 2 | AA12: =X12-Z12 -> 8 | AC12: 3 | AD12: =AA12-AC12 -> 5 | AF12: 3 | AG12: =AD12-AF12 -> 2 | AI12: 2 | AJ12: =AG12-AI12 -> 0 | AM12: =AJ12-AL12 -> 0 | AP12: =AM12-AO12 -> 0 | AS12: =AP12-AR12 -> 0 | AV12: =AS12-AU12 -> 0 | AY12: =AV12-AX12 -> 0 | BB12: =AY12-BA12 -> 0 | BE12: =BB12-BD12 -> 0 | BH12: =BE12-BG12 -> 0 | BK12: =BH12-BJ12 -> 0 | BN12: =BK12-BM12 -> 0 | BP12: =H12+K12+N12+Q12+T12+W12+Z12+AC12+AF12+AI12+AL12+AO12+AR12+AU12+AX12+BA12+BD12+BG12+BJ12+BM12 -> 10 | BQ12: =G12-BP12 -> 0
D13: Crear el repositorio del proyecto en GitHub | E13: Yosvani | F13: Hecho | G13: 2 | I13: =G13-H13 -> 2 | L13: =I13-K13 -> 2 | O13: =L13-N13 -> 2 | R13: =O13-Q13 -> 2 | U13: =R13-T13 -> 2 | X13: =U13-W13 -> 2 | AA13: =X13-Z13 -> 2 | AD13: =AA13-AC13 -> 2 | AG13: =AD13-AF13 -> 2 | AI13: 2 | AJ13: =AG13-AI13 -> 0 | AM13: =AJ13-AL13 -> 0 | AP13: =AM13-AO13 -> 0 | AS13: =AP13-AR13 -> 0 | AV13: =AS13-AU13 -> 0 | AY13: =AV13-AX13 -> 0 | BB13: =AY13-BA13 -> 0 | BE13: =BB13-BD13 -> 0 | BH13: =BE13-BG13 -> 0 | BK13: =BH13-BJ13 -> 0 | BN13: =BK13-BM13 -> 0 | BP13: =H13+K13+N13+Q13+T13+W13+Z13+AC13+AF13+AI13+AL13+AO13+AR13+AU13+AX13+BA13+BD13+BG13+BJ13+BM13 -> 2 | BQ13: =G13-BP13 -> 0
B15: Sprint 3 · 07/09/2026 al 20/09/2026 · Desarrollo de login y conexión a la base de datos HU-AUTH-0001 | C15: Como un usuario, necesito iniciar sesión con mi correo y contraseña, con la finalidad de acceder de forma segura a mi perfil | D15: Implementar el login unificado | E15: Yosvani | F15: Hecho | G15: 3 | H15: 3 | I15: =G15-H15 -> 0 | L15: =I15-K15 -> 0 | O15: =L15-N15 -> 0 | R15: =O15-Q15 -> 0 | U15: =R15-T15 -> 0 | X15: =U15-W15 -> 0 | AA15: =X15-Z15 -> 0 | AD15: =AA15-AC15 -> 0 | AG15: =AD15-AF15 -> 0 | AJ15: =AG15-AI15 -> 0 | AM15: =AJ15-AL15 -> 0 | AP15: =AM15-AO15 -> 0 | AS15: =AP15-AR15 -> 0 | AV15: =AS15-AU15 -> 0 | AY15: =AV15-AX15 -> 0 | BB15: =AY15-BA15 -> 0 | BE15: =BB15-BD15 -> 0 | BH15: =BE15-BG15 -> 0 | BK15: =BH15-BJ15 -> 0 | BN15: =BK15-BM15 -> 0 | BP15: =H15+K15+N15+Q15+T15+W15+Z15+AC15+AF15+AI15+AL15+AO15+AR15+AU15+AX15+BA15+BD15+BG15+BJ15+BM15 -> 3 | BQ15: =G15-BP15 -> 0
B16: HU-AUTH-0002 | C16: Como un usuario, necesito que el sistema verifique si mi correo ya está registrado, con la finalidad de guiarme al flujo de acceso correcto | D16: Implementar la verificación de correo | E16: Yosvani | F16: Hecho | G16: 1 | I16: =G16-H16 -> 1 | K16: 1 | L16: =I16-K16 -> 0 | O16: =L16-N16 -> 0 | R16: =O16-Q16 -> 0 | U16: =R16-T16 -> 0 | X16: =U16-W16 -> 0 | AA16: =X16-Z16 -> 0 | AD16: =AA16-AC16 -> 0 | AG16: =AD16-AF16 -> 0 | AJ16: =AG16-AI16 -> 0 | AM16: =AJ16-AL16 -> 0 | AP16: =AM16-AO16 -> 0 | AS16: =AP16-AR16 -> 0 | AV16: =AS16-AU16 -> 0 | AY16: =AV16-AX16 -> 0 | BB16: =AY16-BA16 -> 0 | BE16: =BB16-BD16 -> 0 | BH16: =BE16-BG16 -> 0 | BK16: =BH16-BJ16 -> 0 | BN16: =BK16-BM16 -> 0 | BP16: =H16+K16+N16+Q16+T16+W16+Z16+AC16+AF16+AI16+AL16+AO16+AR16+AU16+AX16+BA16+BD16+BG16+BJ16+BM16 -> 1 | BQ16: =G16-BP16 -> 0
B17: HU-AUTH-0003 | C17: Como un usuario nuevo, necesito activar mi cuenta con un código enviado a mi correo, con la finalidad de validar mi identidad antes de usar la app | D17: Implementar la activación de cuenta con código | E17: Yosvani | F17: Hecho | G17: 3 | I17: =G17-H17 -> 3 | K17: 2 | L17: =I17-K17 -> 1 | N17: 1 | O17: =L17-N17 -> 0 | R17: =O17-Q17 -> 0 | U17: =R17-T17 -> 0 | X17: =U17-W17 -> 0 | AA17: =X17-Z17 -> 0 | AD17: =AA17-AC17 -> 0 | AG17: =AD17-AF17 -> 0 | AJ17: =AG17-AI17 -> 0 | AM17: =AJ17-AL17 -> 0 | AP17: =AM17-AO17 -> 0 | AS17: =AP17-AR17 -> 0 | AV17: =AS17-AU17 -> 0 | AY17: =AV17-AX17 -> 0 | BB17: =AY17-BA17 -> 0 | BE17: =BB17-BD17 -> 0 | BH17: =BE17-BG17 -> 0 | BK17: =BH17-BJ17 -> 0 | BN17: =BK17-BM17 -> 0 | BP17: =H17+K17+N17+Q17+T17+W17+Z17+AC17+AF17+AI17+AL17+AO17+AR17+AU17+AX17+BA17+BD17+BG17+BJ17+BM17 -> 3 | BQ17: =G17-BP17 -> 0
B18: HU-AUTH-0004 | C18: Como un usuario nuevo, necesito crear mi contraseña inicial cumpliendo requisitos de seguridad, con la finalidad de proteger mi cuenta | D18: Implementar la creación de la contraseña inicial | E18: Yosvani | F18: Hecho | G18: 2 | I18: =G18-H18 -> 2 | L18: =I18-K18 -> 2 | N18: 2 | O18: =L18-N18 -> 0 | R18: =O18-Q18 -> 0 | U18: =R18-T18 -> 0 | X18: =U18-W18 -> 0 | AA18: =X18-Z18 -> 0 | AD18: =AA18-AC18 -> 0 | AG18: =AD18-AF18 -> 0 | AJ18: =AG18-AI18 -> 0 | AM18: =AJ18-AL18 -> 0 | AP18: =AM18-AO18 -> 0 | AS18: =AP18-AR18 -> 0 | AV18: =AS18-AU18 -> 0 | AY18: =AV18-AX18 -> 0 | BB18: =AY18-BA18 -> 0 | BE18: =BB18-BD18 -> 0 | BH18: =BE18-BG18 -> 0 | BK18: =BH18-BJ18 -> 0 | BN18: =BK18-BM18 -> 0 | BP18: =H18+K18+N18+Q18+T18+W18+Z18+AC18+AF18+AI18+AL18+AO18+AR18+AU18+AX18+BA18+BD18+BG18+BJ18+BM18 -> 2 | BQ18: =G18-BP18 -> 0
B19: HU-AUTH-0005 | C19: Como un usuario, necesito recuperar mi contraseña mediante un código enviado a mi correo, con la finalidad de volver a ingresar si la olvido | D19: Implementar el flujo de recuperación de contraseña | E19: Yosvani | F19: Hecho | G19: 3 | I19: =G19-H19 -> 3 | L19: =I19-K19 -> 3 | O19: =L19-N19 -> 3 | Q19: 3 | R19: =O19-Q19 -> 0 | U19: =R19-T19 -> 0 | X19: =U19-W19 -> 0 | AA19: =X19-Z19 -> 0 | AD19: =AA19-AC19 -> 0 | AG19: =AD19-AF19 -> 0 | AJ19: =AG19-AI19 -> 0 | AM19: =AJ19-AL19 -> 0 | AP19: =AM19-AO19 -> 0 | AS19: =AP19-AR19 -> 0 | AV19: =AS19-AU19 -> 0 | AY19: =AV19-AX19 -> 0 | BB19: =AY19-BA19 -> 0 | BE19: =BB19-BD19 -> 0 | BH19: =BE19-BG19 -> 0 | BK19: =BH19-BJ19 -> 0 | BN19: =BK19-BM19 -> 0 | BP19: =H19+K19+N19+Q19+T19+W19+Z19+AC19+AF19+AI19+AL19+AO19+AR19+AU19+AX19+BA19+BD19+BG19+BJ19+BM19 -> 3 | BQ19: =G19-BP19 -> 0
B20: HU-AUTH-0007 | C20: Como un usuario, necesito cerrar sesión desde mi perfil, con la finalidad de proteger mi cuenta en dispositivos compartidos | D20: Agregar cerrar sesión en el perfil | E20: Yosvani | F20: Hecho | G20: 1 | I20: =G20-H20 -> 1 | L20: =I20-K20 -> 1 | O20: =L20-N20 -> 1 | R20: =O20-Q20 -> 1 | T20: 1 | U20: =R20-T20 -> 0 | X20: =U20-W20 -> 0 | AA20: =X20-Z20 -> 0 | AD20: =AA20-AC20 -> 0 | AG20: =AD20-AF20 -> 0 | AJ20: =AG20-AI20 -> 0 | AM20: =AJ20-AL20 -> 0 | AP20: =AM20-AO20 -> 0 | AS20: =AP20-AR20 -> 0 | AV20: =AS20-AU20 -> 0 | AY20: =AV20-AX20 -> 0 | BB20: =AY20-BA20 -> 0 | BE20: =BB20-BD20 -> 0 | BH20: =BE20-BG20 -> 0 | BK20: =BH20-BJ20 -> 0 | BN20: =BK20-BM20 -> 0 | BP20: =H20+K20+N20+Q20+T20+W20+Z20+AC20+AF20+AI20+AL20+AO20+AR20+AU20+AX20+BA20+BD20+BG20+BJ20+BM20 -> 1 | BQ20: =G20-BP20 -> 0
B21: HU-AUTH-0008 | C21: Como un usuario, necesito que mi sesión se guarde de forma segura en el dispositivo, con la finalidad de no tener que iniciar sesión cada vez | D21: Implementar la persistencia segura de la sesión | E21: Yosvani | F21: Hecho | G21: 1 | I21: =G21-H21 -> 1 | L21: =I21-K21 -> 1 | O21: =L21-N21 -> 1 | R21: =O21-Q21 -> 1 | T21: 1 | U21: =R21-T21 -> 0 | X21: =U21-W21 -> 0 | AA21: =X21-Z21 -> 0 | AD21: =AA21-AC21 -> 0 | AG21: =AD21-AF21 -> 0 | AJ21: =AG21-AI21 -> 0 | AM21: =AJ21-AL21 -> 0 | AP21: =AM21-AO21 -> 0 | AS21: =AP21-AR21 -> 0 | AV21: =AS21-AU21 -> 0 | AY21: =AV21-AX21 -> 0 | BB21: =AY21-BA21 -> 0 | BE21: =BB21-BD21 -> 0 | BH21: =BE21-BG21 -> 0 | BK21: =BH21-BJ21 -> 0 | BN21: =BK21-BM21 -> 0 | BP21: =H21+K21+N21+Q21+T21+W21+Z21+AC21+AF21+AI21+AL21+AO21+AR21+AU21+AX21+BA21+BD21+BG21+BJ21+BM21 -> 1 | BQ21: =G21-BP21 -> 0
B22: HU-SEGU-0001 | C22: Como un usuario, necesito leer y aceptar los términos de tratamiento de datos (Ley N° 21.719) al ingresar, con la finalidad de autorizar el uso de mi información | D22: Integrar el consentimiento de la Ley N° 21.719 | E22: Yosvani | F22: Hecho | G22: 2 | I22: =G22-H22 -> 2 | L22: =I22-K22 -> 2 | O22: =L22-N22 -> 2 | R22: =O22-Q22 -> 2 | T22: 1 | U22: =R22-T22 -> 1 | W22: 1 | X22: =U22-W22 -> 0 | AA22: =X22-Z22 -> 0 | AD22: =AA22-AC22 -> 0 | AG22: =AD22-AF22 -> 0 | AJ22: =AG22-AI22 -> 0 | AM22: =AJ22-AL22 -> 0 | AP22: =AM22-AO22 -> 0 | AS22: =AP22-AR22 -> 0 | AV22: =AS22-AU22 -> 0 | AY22: =AV22-AX22 -> 0 | BB22: =AY22-BA22 -> 0 | BE22: =BB22-BD22 -> 0 | BH22: =BE22-BG22 -> 0 | BK22: =BH22-BJ22 -> 0 | BN22: =BK22-BM22 -> 0 | BP22: =H22+K22+N22+Q22+T22+W22+Z22+AC22+AF22+AI22+AL22+AO22+AR22+AU22+AX22+BA22+BD22+BG22+BJ22+BM22 -> 2 | BQ22: =G22-BP22 -> 0
D23: Realizar la auditoría legal de la Ley N° 21.719 | E23: Yosvani | F23: Hecho | G23: 2 | I23: =G23-H23 -> 2 | L23: =I23-K23 -> 2 | O23: =L23-N23 -> 2 | R23: =O23-Q23 -> 2 | U23: =R23-T23 -> 2 | W23: 2 | X23: =U23-W23 -> 0 | AA23: =X23-Z23 -> 0 | AD23: =AA23-AC23 -> 0 | AG23: =AD23-AF23 -> 0 | AJ23: =AG23-AI23 -> 0 | AM23: =AJ23-AL23 -> 0 | AP23: =AM23-AO23 -> 0 | AS23: =AP23-AR23 -> 0 | AV23: =AS23-AU23 -> 0 | AY23: =AV23-AX23 -> 0 | BB23: =AY23-BA23 -> 0 | BE23: =BB23-BD23 -> 0 | BH23: =BE23-BG23 -> 0 | BK23: =BH23-BJ23 -> 0 | BN23: =BK23-BM23 -> 0 | BP23: =H23+K23+N23+Q23+T23+W23+Z23+AC23+AF23+AI23+AL23+AO23+AR23+AU23+AX23+BA23+BD23+BG23+BJ23+BM23 -> 2 | BQ23: =G23-BP23 -> 0
B24: HU-SEGU-0002 | C24: Como un usuario del sistema, necesito que cada perfil solo acceda a la información que le corresponde, con la finalidad de proteger datos sensibles de salud | D24: Implementar la autenticación con JWT | E24: Yosvani | F24: Hecho | G24: 2 | I24: =G24-H24 -> 2 | L24: =I24-K24 -> 2 | O24: =L24-N24 -> 2 | R24: =O24-Q24 -> 2 | U24: =R24-T24 -> 2 | X24: =U24-W24 -> 2 | Z24: 2 | AA24: =X24-Z24 -> 0 | AD24: =AA24-AC24 -> 0 | AG24: =AD24-AF24 -> 0 | AJ24: =AG24-AI24 -> 0 | AM24: =AJ24-AL24 -> 0 | AP24: =AM24-AO24 -> 0 | AS24: =AP24-AR24 -> 0 | AV24: =AS24-AU24 -> 0 | AY24: =AV24-AX24 -> 0 | BB24: =AY24-BA24 -> 0 | BE24: =BB24-BD24 -> 0 | BH24: =BE24-BG24 -> 0 | BK24: =BH24-BJ24 -> 0 | BN24: =BK24-BM24 -> 0 | BP24: =H24+K24+N24+Q24+T24+W24+Z24+AC24+AF24+AI24+AL24+AO24+AR24+AU24+AX24+BA24+BD24+BG24+BJ24+BM24 -> 2 | BQ24: =G24-BP24 -> 0
D25: Mitigar las vulnerabilidades BOLA/IDOR | E25: Yosvani | F25: Hecho | G25: 2 | I25: =G25-H25 -> 2 | L25: =I25-K25 -> 2 | O25: =L25-N25 -> 2 | R25: =O25-Q25 -> 2 | U25: =R25-T25 -> 2 | X25: =U25-W25 -> 2 | Z25: 1 | AA25: =X25-Z25 -> 1 | AC25: 1 | AD25: =AA25-AC25 -> 0 | AG25: =AD25-AF25 -> 0 | AJ25: =AG25-AI25 -> 0 | AM25: =AJ25-AL25 -> 0 | AP25: =AM25-AO25 -> 0 | AS25: =AP25-AR25 -> 0 | AV25: =AS25-AU25 -> 0 | AY25: =AV25-AX25 -> 0 | BB25: =AY25-BA25 -> 0 | BE25: =BB25-BD25 -> 0 | BH25: =BE25-BG25 -> 0 | BK25: =BH25-BJ25 -> 0 | BN25: =BK25-BM25 -> 0 | BP25: =H25+K25+N25+Q25+T25+W25+Z25+AC25+AF25+AI25+AL25+AO25+AR25+AU25+AX25+BA25+BD25+BG25+BJ25+BM25 -> 2 | BQ25: =G25-BP25 -> 0
B26: HU-SEGU-0003 | C26: Como un usuario, necesito que el sistema limite los intentos repetidos de acceso y de códigos, con la finalidad de evitar abusos y ataques de fuerza bruta | D26: Implementar rate limiting | F26: Hecho | G26: 4 | I26: =G26-H26 -> 4 | L26: =I26-K26 -> 4 | N26: 1 | O26: =L26-N26 -> 3 | R26: =O26-Q26 -> 3 | T26: 1 | U26: =R26-T26 -> 2 | X26: =U26-W26 -> 2 | AA26: =X26-Z26 -> 2 | AC26: 1 | AD26: =AA26-AC26 -> 1 | AG26: =AD26-AF26 -> 1 | AI26: 1 | AJ26: =AG26-AI26 -> 0 | AM26: =AJ26-AL26 -> 0 | AP26: =AM26-AO26 -> 0 | AS26: =AP26-AR26 -> 0 | AV26: =AS26-AU26 -> 0 | AY26: =AV26-AX26 -> 0 | BB26: =AY26-BA26 -> 0 | BE26: =BB26-BD26 -> 0 | BH26: =BE26-BG26 -> 0 | BK26: =BH26-BJ26 -> 0 | BN26: =BK26-BM26 -> 0 | BP26: =H26+K26+N26+Q26+T26+W26+Z26+AC26+AF26+AI26+AL26+AO26+AR26+AU26+AX26+BA26+BD26+BG26+BJ26+BM26 -> 4 | BQ26: =G26-BP26 -> 0
B27: N/A | C27: Sin historia de usuario (tareas técnicas del proyecto) | D27: Reestructurar el proyecto en FrontEnd, BackEnd y schema.sql | E27: Yosvani | F27: Hecho | G27: 2 | I27: =G27-H27 -> 2 | L27: =I27-K27 -> 2 | O27: =L27-N27 -> 2 | R27: =O27-Q27 -> 2 | U27: =R27-T27 -> 2 | X27: =U27-W27 -> 2 | AA27: =X27-Z27 -> 2 | AC27: 2 | AD27: =AA27-AC27 -> 0 | AG27: =AD27-AF27 -> 0 | AJ27: =AG27-AI27 -> 0 | AM27: =AJ27-AL27 -> 0 | AP27: =AM27-AO27 -> 0 | AS27: =AP27-AR27 -> 0 | AV27: =AS27-AU27 -> 0 | AY27: =AV27-AX27 -> 0 | BB27: =AY27-BA27 -> 0 | BE27: =BB27-BD27 -> 0 | BH27: =BE27-BG27 -> 0 | BK27: =BH27-BJ27 -> 0 | BN27: =BK27-BM27 -> 0 | BP27: =H27+K27+N27+Q27+T27+W27+Z27+AC27+AF27+AI27+AL27+AO27+AR27+AU27+AX27+BA27+BD27+BG27+BJ27+BM27 -> 2 | BQ27: =G27-BP27 -> 0
D28: Implementar la API del backend e integrarla con la app | E28: Yosvani | F28: Hecho | G28: 5 | I28: =G28-H28 -> 5 | L28: =I28-K28 -> 5 | O28: =L28-N28 -> 5 | R28: =O28-Q28 -> 5 | U28: =R28-T28 -> 5 | X28: =U28-W28 -> 5 | AA28: =X28-Z28 -> 5 | AD28: =AA28-AC28 -> 5 | AF28: 3 | AG28: =AD28-AF28 -> 2 | AI28: 2 | AJ28: =AG28-AI28 -> 0 | AM28: =AJ28-AL28 -> 0 | AP28: =AM28-AO28 -> 0 | AS28: =AP28-AR28 -> 0 | AV28: =AS28-AU28 -> 0 | AY28: =AV28-AX28 -> 0 | BB28: =AY28-BA28 -> 0 | BE28: =BB28-BD28 -> 0 | BH28: =BE28-BG28 -> 0 | BK28: =BH28-BJ28 -> 0 | BN28: =BK28-BM28 -> 0 | BP28: =H28+K28+N28+Q28+T28+W28+Z28+AC28+AF28+AI28+AL28+AO28+AR28+AU28+AX28+BA28+BD28+BG28+BJ28+BM28 -> 5 | BQ28: =G28-BP28 -> 0
D29: Resolver la IP de la API de forma dinámica | E29: Yosvani | F29: Hecho | G29: 1 | I29: =G29-H29 -> 1 | L29: =I29-K29 -> 1 | O29: =L29-N29 -> 1 | R29: =O29-Q29 -> 1 | U29: =R29-T29 -> 1 | X29: =U29-W29 -> 1 | AA29: =X29-Z29 -> 1 | AD29: =AA29-AC29 -> 1 | AG29: =AD29-AF29 -> 1 | AI29: 1 | AJ29: =AG29-AI29 -> 0 | AM29: =AJ29-AL29 -> 0 | AP29: =AM29-AO29 -> 0 | AS29: =AP29-AR29 -> 0 | AV29: =AS29-AU29 -> 0 | AY29: =AV29-AX29 -> 0 | BB29: =AY29-BA29 -> 0 | BE29: =BB29-BD29 -> 0 | BH29: =BE29-BG29 -> 0 | BK29: =BH29-BJ29 -> 0 | BN29: =BK29-BM29 -> 0 | BP29: =H29+K29+N29+Q29+T29+W29+Z29+AC29+AF29+AI29+AL29+AO29+AR29+AU29+AX29+BA29+BD29+BG29+BJ29+BM29 -> 1 | BQ29: =G29-BP29 -> 0
B31: Sprint 4 · 21/09/2026 al 04/10/2026 · Desarrollo de la vista del paciente HU-HABI-0001 | C31: Como un paciente, necesito registrar cada día mis seis hábitos (comida, ejercicio, hidratación, sueño, ansiedad y estrés), con la finalidad de dar seguimiento a mi bienestar | D31: Implementar la validación de los 6 hábitos | E31: Yosvani | F31: Hecho | G31: 8 | H31: 2 | I31: =G31-H31 -> 6 | K31: 2 | L31: =I31-K31 -> 4 | N31: 2 | O31: =L31-N31 -> 2 | Q31: 2 | R31: =O31-Q31 -> 0 | U31: =R31-T31 -> 0 | X31: =U31-W31 -> 0 | AA31: =X31-Z31 -> 0 | AD31: =AA31-AC31 -> 0 | AG31: =AD31-AF31 -> 0 | AJ31: =AG31-AI31 -> 0 | AM31: =AJ31-AL31 -> 0 | AP31: =AM31-AO31 -> 0 | AS31: =AP31-AR31 -> 0 | AV31: =AS31-AU31 -> 0 | AY31: =AV31-AX31 -> 0 | BB31: =AY31-BA31 -> 0 | BE31: =BB31-BD31 -> 0 | BH31: =BE31-BG31 -> 0 | BK31: =BH31-BJ31 -> 0 | BN31: =BK31-BM31 -> 0 | BP31: =H31+K31+N31+Q31+T31+W31+Z31+AC31+AF31+AI31+AL31+AO31+AR31+AU31+AX31+BA31+BD31+BG31+BJ31+BM31 -> 8 | BQ31: =G31-BP31 -> 0
D32: Ajustar colores, tarjetas y textos de la pestaña de hábitos | E32: Vanessa | F32: Hecho | G32: 8 | H32: 2 | I32: =G32-H32 -> 6 | K32: 2 | L32: =I32-K32 -> 4 | N32: 2 | O32: =L32-N32 -> 2 | Q32: 2 | R32: =O32-Q32 -> 0 | U32: =R32-T32 -> 0 | X32: =U32-W32 -> 0 | AA32: =X32-Z32 -> 0 | AD32: =AA32-AC32 -> 0 | AG32: =AD32-AF32 -> 0 | AJ32: =AG32-AI32 -> 0 | AM32: =AJ32-AL32 -> 0 | AP32: =AM32-AO32 -> 0 | AS32: =AP32-AR32 -> 0 | AV32: =AS32-AU32 -> 0 | AY32: =AV32-AX32 -> 0 | BB32: =AY32-BA32 -> 0 | BE32: =BB32-BD32 -> 0 | BH32: =BE32-BG32 -> 0 | BK32: =BH32-BJ32 -> 0 | BN32: =BK32-BM32 -> 0 | BP32: =H32+K32+N32+Q32+T32+W32+Z32+AC32+AF32+AI32+AL32+AO32+AR32+AU32+AX32+BA32+BD32+BG32+BJ32+BM32 -> 8 | BQ32: =G32-BP32 -> 0
B33: HU-HABI-0002 | C33: Como un paciente, necesito indicar los litros de agua y las horas de sueño, con la finalidad de que mi registro sea más preciso | D33: Integrar el registro de litros de hidratación y horas de sueño | E33: Yosvani | F33: Hecho | G33: 4 | I33: =G33-H33 -> 4 | L33: =I33-K33 -> 4 | O33: =L33-N33 -> 4 | Q33: 1 | R33: =O33-Q33 -> 3 | T33: 2 | U33: =R33-T33 -> 1 | W33: 1 | X33: =U33-W33 -> 0 | AA33: =X33-Z33 -> 0 | AD33: =AA33-AC33 -> 0 | AG33: =AD33-AF33 -> 0 | AJ33: =AG33-AI33 -> 0 | AM33: =AJ33-AL33 -> 0 | AP33: =AM33-AO33 -> 0 | AS33: =AP33-AR33 -> 0 | AV33: =AS33-AU33 -> 0 | AY33: =AV33-AX33 -> 0 | BB33: =AY33-BA33 -> 0 | BE33: =BB33-BD33 -> 0 | BH33: =BE33-BG33 -> 0 | BK33: =BH33-BJ33 -> 0 | BN33: =BK33-BM33 -> 0 | BP33: =H33+K33+N33+Q33+T33+W33+Z33+AC33+AF33+AI33+AL33+AO33+AR33+AU33+AX33+BA33+BD33+BG33+BJ33+BM33 -> 4 | BQ33: =G33-BP33 -> 0
B34: HU-HABI-0003 | C34: Como un paciente, necesito ver cuántos hábitos llevo registrados hoy, con la finalidad de saber cuánto me falta por completar | D34: Mostrar el avance del día (n/6) | E34: Ambos | F34: Hecho | G34: 4 | I34: =G34-H34 -> 4 | L34: =I34-K34 -> 4 | O34: =L34-N34 -> 4 | R34: =O34-Q34 -> 4 | T34: 2 | U34: =R34-T34 -> 2 | W34: 1 | X34: =U34-W34 -> 1 | Z34: 1 | AA34: =X34-Z34 -> 0 | AD34: =AA34-AC34 -> 0 | AG34: =AD34-AF34 -> 0 | AJ34: =AG34-AI34 -> 0 | AM34: =AJ34-AL34 -> 0 | AP34: =AM34-AO34 -> 0 | AS34: =AP34-AR34 -> 0 | AV34: =AS34-AU34 -> 0 | AY34: =AV34-AX34 -> 0 | BB34: =AY34-BA34 -> 0 | BE34: =BB34-BD34 -> 0 | BH34: =BE34-BG34 -> 0 | BK34: =BH34-BJ34 -> 0 | BN34: =BK34-BM34 -> 0 | BP34: =H34+K34+N34+Q34+T34+W34+Z34+AC34+AF34+AI34+AL34+AO34+AR34+AU34+AX34+BA34+BD34+BG34+BJ34+BM34 -> 4 | BQ34: =G34-BP34 -> 0
B35: HU-HABI-0004 | C35: Como un paciente, necesito que, una vez registrados los hábitos del día, no se puedan duplicar, con la finalidad de mantener un registro consistente | D35: Evitar que se duplique el registro del día | E35: Ambos | F35: Hecho | G35: 4 | I35: =G35-H35 -> 4 | L35: =I35-K35 -> 4 | O35: =L35-N35 -> 4 | R35: =O35-Q35 -> 4 | U35: =R35-T35 -> 4 | W35: 2 | X35: =U35-W35 -> 2 | Z35: 2 | AA35: =X35-Z35 -> 0 | AD35: =AA35-AC35 -> 0 | AG35: =AD35-AF35 -> 0 | AJ35: =AG35-AI35 -> 0 | AM35: =AJ35-AL35 -> 0 | AP35: =AM35-AO35 -> 0 | AS35: =AP35-AR35 -> 0 | AV35: =AS35-AU35 -> 0 | AY35: =AV35-AX35 -> 0 | BB35: =AY35-BA35 -> 0 | BE35: =BB35-BD35 -> 0 | BH35: =BE35-BG35 -> 0 | BK35: =BH35-BJ35 -> 0 | BN35: =BK35-BM35 -> 0 | BP35: =H35+K35+N35+Q35+T35+W35+Z35+AC35+AF35+AI35+AL35+AO35+AR35+AU35+AX35+BA35+BD35+BG35+BJ35+BM35 -> 4 | BQ35: =G35-BP35 -> 0
B36: HU-EJER-0001 | C36: Como un paciente, necesito acceder a ejercicios de respiración y relajación para ansiedad, sueño y estrés, con la finalidad de trabajar mis hábitos entre sesiones | D36: Crear el catálogo de recursos del paciente | E36: Yosvani | F36: Hecho | G36: 3 | I36: =G36-H36 -> 3 | L36: =I36-K36 -> 3 | O36: =L36-N36 -> 3 | R36: =O36-Q36 -> 3 | U36: =R36-T36 -> 3 | X36: =U36-W36 -> 3 | AA36: =X36-Z36 -> 3 | AC36: 2 | AD36: =AA36-AC36 -> 1 | AF36: 1 | AG36: =AD36-AF36 -> 0 | AJ36: =AG36-AI36 -> 0 | AM36: =AJ36-AL36 -> 0 | AP36: =AM36-AO36 -> 0 | AS36: =AP36-AR36 -> 0 | AV36: =AS36-AU36 -> 0 | AY36: =AV36-AX36 -> 0 | BB36: =AY36-BA36 -> 0 | BE36: =BB36-BD36 -> 0 | BH36: =BE36-BG36 -> 0 | BK36: =BH36-BJ36 -> 0 | BN36: =BK36-BM36 -> 0 | BP36: =H36+K36+N36+Q36+T36+W36+Z36+AC36+AF36+AI36+AL36+AO36+AR36+AU36+AX36+BA36+BD36+BG36+BJ36+BM36 -> 3 | BQ36: =G36-BP36 -> 0
D37: Ajustar textos y diseño de la pestaña de ejercicios | E37: Vanessa | F37: Hecho | G37: 3 | I37: =G37-H37 -> 3 | L37: =I37-K37 -> 3 | O37: =L37-N37 -> 3 | R37: =O37-Q37 -> 3 | U37: =R37-T37 -> 3 | X37: =U37-W37 -> 3 | Z37: 2 | AA37: =X37-Z37 -> 1 | AC37: 1 | AD37: =AA37-AC37 -> 0 | AG37: =AD37-AF37 -> 0 | AJ37: =AG37-AI37 -> 0 | AM37: =AJ37-AL37 -> 0 | AP37: =AM37-AO37 -> 0 | AS37: =AP37-AR37 -> 0 | AV37: =AS37-AU37 -> 0 | AY37: =AV37-AX37 -> 0 | BB37: =AY37-BA37 -> 0 | BE37: =BB37-BD37 -> 0 | BH37: =BE37-BG37 -> 0 | BK37: =BH37-BJ37 -> 0 | BN37: =BK37-BM37 -> 0 | BP37: =H37+K37+N37+Q37+T37+W37+Z37+AC37+AF37+AI37+AL37+AO37+AR37+AU37+AX37+BA37+BD37+BG37+BJ37+BM37 -> 3 | BQ37: =G37-BP37 -> 0
B38: HU-EJER-0002 | C38: Como un paciente, necesito ver videos de ejemplo de cada ejercicio, con la finalidad de realizarlos correctamente | D38: Cargar los videos reales de los ejercicios | F38: Por iniciar | G38: 6 | I38: =G38-H38 -> 6 | L38: =I38-K38 -> 6 | O38: =L38-N38 -> 6 | R38: =O38-Q38 -> 6 | U38: =R38-T38 -> 6 | X38: =U38-W38 -> 6 | AA38: =X38-Z38 -> 6 | AD38: =AA38-AC38 -> 6 | AG38: =AD38-AF38 -> 6 | AJ38: =AG38-AI38 -> 6 | AM38: =AJ38-AL38 -> 6 | AP38: =AM38-AO38 -> 6 | AS38: =AP38-AR38 -> 6 | AV38: =AS38-AU38 -> 6 | AY38: =AV38-AX38 -> 6 | BB38: =AY38-BA38 -> 6 | BE38: =BB38-BD38 -> 6 | BH38: =BE38-BG38 -> 6 | BK38: =BH38-BJ38 -> 6 | BN38: =BK38-BM38 -> 6 | BP38: =H38+K38+N38+Q38+T38+W38+Z38+AC38+AF38+AI38+AL38+AO38+AR38+AU38+AX38+BA38+BD38+BG38+BJ38+BM38 -> 0 | BQ38: =G38-BP38 -> 6
B39: HU-SESI-0001 | C39: Como un paciente, necesito ver mis próximas citas y mi historial de sesiones, con la finalidad de organizar mi proceso terapéutico | D39: Ajustar iconos, colores y pantalla de sesiones del paciente | E39: Vanessa | F39: Hecho | G39: 6 | I39: =G39-H39 -> 6 | L39: =I39-K39 -> 6 | O39: =L39-N39 -> 6 | R39: =O39-Q39 -> 6 | U39: =R39-T39 -> 6 | X39: =U39-W39 -> 6 | AA39: =X39-Z39 -> 6 | AC39: 1 | AD39: =AA39-AC39 -> 5 | AF39: 2 | AG39: =AD39-AF39 -> 3 | AI39: 3 | AJ39: =AG39-AI39 -> 0 | AM39: =AJ39-AL39 -> 0 | AP39: =AM39-AO39 -> 0 | AS39: =AP39-AR39 -> 0 | AV39: =AS39-AU39 -> 0 | AY39: =AV39-AX39 -> 0 | BB39: =AY39-BA39 -> 0 | BE39: =BB39-BD39 -> 0 | BH39: =BE39-BG39 -> 0 | BK39: =BH39-BJ39 -> 0 | BN39: =BK39-BM39 -> 0 | BP39: =H39+K39+N39+Q39+T39+W39+Z39+AC39+AF39+AI39+AL39+AO39+AR39+AU39+AX39+BA39+BD39+BG39+BJ39+BM39 -> 6 | BQ39: =G39-BP39 -> 0
B40: HU-PERF-0001 | C40: Como un paciente, necesito ver mi perfil y mi psicólogo asignado, con la finalidad de conocer mis datos y quién atiende mi caso | D40: Implementar el perfil del paciente | E40: Yosvani | F40: Hecho | G40: 4 | I40: =G40-H40 -> 4 | L40: =I40-K40 -> 4 | O40: =L40-N40 -> 4 | R40: =O40-Q40 -> 4 | U40: =R40-T40 -> 4 | X40: =U40-W40 -> 4 | AA40: =X40-Z40 -> 4 | AD40: =AA40-AC40 -> 4 | AF40: 1 | AG40: =AD40-AF40 -> 3 | AI40: 3 | AJ40: =AG40-AI40 -> 0 | AM40: =AJ40-AL40 -> 0 | AP40: =AM40-AO40 -> 0 | AS40: =AP40-AR40 -> 0 | AV40: =AS40-AU40 -> 0 | AY40: =AV40-AX40 -> 0 | BB40: =AY40-BA40 -> 0 | BE40: =BB40-BD40 -> 0 | BH40: =BE40-BG40 -> 0 | BK40: =BH40-BJ40 -> 0 | BN40: =BK40-BM40 -> 0 | BP40: =H40+K40+N40+Q40+T40+W40+Z40+AC40+AF40+AI40+AL40+AO40+AR40+AU40+AX40+BA40+BD40+BG40+BJ40+BM40 -> 4 | BQ40: =G40-BP40 -> 0
I41: =G41-H41 -> 0 | L41: =I41-K41 -> 0 | O41: =L41-N41 -> 0 | R41: =O41-Q41 -> 0 | U41: =R41-T41 -> 0 | X41: =U41-W41 -> 0 | AA41: =X41-Z41 -> 0 | AD41: =AA41-AC41 -> 0 | AG41: =AD41-AF41 -> 0 | AJ41: =AG41-AI41 -> 0 | AM41: =AJ41-AL41 -> 0 | AP41: =AM41-AO41 -> 0 | AS41: =AP41-AR41 -> 0 | AV41: =AS41-AU41 -> 0 | AY41: =AV41-AX41 -> 0 | BB41: =AY41-BA41 -> 0 | BE41: =BB41-BD41 -> 0 | BH41: =BE41-BG41 -> 0 | BK41: =BH41-BJ41 -> 0 | BN41: =BK41-BM41 -> 0 | BP41: =H41+K41+N41+Q41+T41+W41+Z41+AC41+AF41+AI41+AL41+AO41+AR41+AU41+AX41+BA41+BD41+BG41+BJ41+BM41 -> 0 | BQ41: =G41-BP41 -> 0
B42: Sprint 5 · 05/10/2026 al 18/10/2026 · Desarrollo de la vista del psicólogo HU-PACI-0001 | C42: Como un psicólogo, necesito registrar a un paciente y verificar si ya existe, con la finalidad de evitar duplicados y asociarlo a mi atención | D42: Implementar el registro de paciente por el psicólogo | E42: Yosvani | F42: Hecho | G42: 0.5 | H42: 0.5 | I42: =G42-H42 -> 0 | L42: =I42-K42 -> 0 | O42: =L42-N42 -> 0 | R42: =O42-Q42 -> 0 | U42: =R42-T42 -> 0 | X42: =U42-W42 -> 0 | AA42: =X42-Z42 -> 0 | AD42: =AA42-AC42 -> 0 | AG42: =AD42-AF42 -> 0 | AJ42: =AG42-AI42 -> 0 | AM42: =AJ42-AL42 -> 0 | AP42: =AM42-AO42 -> 0 | AS42: =AP42-AR42 -> 0 | AV42: =AS42-AU42 -> 0 | AY42: =AV42-AX42 -> 0 | BB42: =AY42-BA42 -> 0 | BE42: =BB42-BD42 -> 0 | BH42: =BE42-BG42 -> 0 | BK42: =BH42-BJ42 -> 0 | BN42: =BK42-BM42 -> 0 | BP42: =H42+K42+N42+Q42+T42+W42+Z42+AC42+AF42+AI42+AL42+AO42+AR42+AU42+AX42+BA42+BD42+BG42+BJ42+BM42 -> 0.5 | BQ42: =G42-BP42 -> 0
D43: Agregar validaciones a los campos del registro | E43: Vanessa | F43: Hecho | G43: 2 | H43: 2 | I43: =G43-H43 -> 0 | L43: =I43-K43 -> 0 | O43: =L43-N43 -> 0 | R43: =O43-Q43 -> 0 | U43: =R43-T43 -> 0 | X43: =U43-W43 -> 0 | AA43: =X43-Z43 -> 0 | AD43: =AA43-AC43 -> 0 | AG43: =AD43-AF43 -> 0 | AJ43: =AG43-AI43 -> 0 | AM43: =AJ43-AL43 -> 0 | AP43: =AM43-AO43 -> 0 | AS43: =AP43-AR43 -> 0 | AV43: =AS43-AU43 -> 0 | AY43: =AV43-AX43 -> 0 | BB43: =AY43-BA43 -> 0 | BE43: =BB43-BD43 -> 0 | BH43: =BE43-BG43 -> 0 | BK43: =BH43-BJ43 -> 0 | BN43: =BK43-BM43 -> 0 | BP43: =H43+K43+N43+Q43+T43+W43+Z43+AC43+AF43+AI43+AL43+AO43+AR43+AU43+AX43+BA43+BD43+BG43+BJ43+BM43 -> 2 | BQ43: =G43-BP43 -> 0
...

Sheet Instructivo
B1: Lista de tareas de la iteración (Product Backlog): Instructivo
B2: Elaborado por: pmoinformatica.com
B4: Columna | C4: Instrucciones
B5: ='Historias de Usuario'!B5 -> Identificador (ID) de item de product backlog | C5: Código que hace referencia al elemento de la pila de producto (Product Backlog) al cual la tarea de la iteración hace referencia.
B6: ='Historias de Usuario'!C5 -> Enunciado del item de Product Backlog | C6: Enunciado o nombre del elemento de pila de producto (Product Backlog). En la mayoría de los casos, el nombre asignado al elemento de product backlog es el mismo de la historia de usuario.
B7: Tarea | C7: Nombre de la tarea de iteración (Sprint) especificada en esta línea, representa el elemento mínimo que se planifica. Para completar un elemento de product backlog / historia se necesitaran ejecutar varias tareas, por ejemplo: Diseñar pantalla, vincular campos con la base de datos, definir procesos, configurar conexiones con interfaces o base de datos, entre otros.
B8: Dueño / Voluntario | C8: Persona integrante del equipo Scrum que ha tomado responsabilidad de la tarea. Se le denomina también voluntario porque en Scrum las tareas no son asignadas por un Gerente o supervisor, sino que cada integrante selecciona la tarea que va a ejecutar en cada reunión diaria. Una persona tomará una o varias tareas en la reunión diaria, y una vez que estas sean completadas (según la definición de "hecho") podrá tomar otras tareas.
B9: Estatus | C9: Estado actual de la tarea. Los tipos de estatus son decididos por el equipo y Scrum Master. Por ejemplo, una clasificación de estatus podría ser: Por iniciar, en proceso y hecho (completado). La clasificación de estatus también se puede vincular con las columnas que se reflejan en un tablero Kanban.
B10: Horas estimadas totales | C10: Horas que han sido estimadas por el equipo Scrum que serán necesarias para ejecutar la tarea. La asignación de estimados se realiza durante la reunión de planificación de la iteración (Sprint Planning Meeting).
B11: Día 1 …. Día n | C11: Una vez comienza a ejecutarse la iteración, se utilizan las columnas para llevar un registro de las horas que se han consumido en cada tarea y cuantas horas restan para completarla.
B12: Cons. | C12: Horas consumidas en la tarea en el día especificado.
B13: Rest. | C13: Horas que restan luego de registrarse el consumo diario. Se calcula tomando las horas que restaban el día anterior y se resta las horas consumidas en el día. Si se trata del primer día, se restan las horas del día 1 al estimado de horas totales.
B14: Total | C14: Registra la suma de todas las horas consumidas en el Sprint y las horas que restan finalmente. Las horas restantes deberían ser de cero si se logro ejecutar la tarea en su totalidad.

Sheet Criterio de estimación
A1: Criterio de estimación de horas
A2: Las horas estimadas salen de los puntos de historia del Product Backlog: horas de la historia = puntos × 2, repartidas en partes iguales entre sus tareas. Las tareas sin historia de usuario (N/A) se estimaron directamente. Son estimaciones iniciales, pendientes de validar por el equipo. Las horas consumidas (Cons.) son una reconstrucción aproximada, explicada más abajo.
A4: Sprint | B4: Tema | C4: Horas estimadas
A5: 1 | B5: Análisis de problemática y solución | C5: =SUM('Historias de Usuario'!G6:G8) -> 28
A6: 2 | B6: Planificación y definición | C6: =SUM('Historias de Usuario'!G10:G13) -> 30
A7: 3 | B7: Login y conexión a BD | C7: =SUM('Historias de Usuario'!G15:G29) -> 34
A8: 4 | B8: Vista del paciente | C8: =SUM('Historias de Usuario'!G31:G40) -> 50
A9: 5 | B9: Vista del psicólogo | C9: =SUM('Historias de Usuario'!G42:G74) -> 54
A10: 6 | B10: Agente H.O.P.E. | C10: =SUM('Historias de Usuario'!G76:G82) -> 88
A11: 7 | B11: Revisiones finales y testing | C11: =SUM('Historias de Usuario'!G84:G86) -> 16
A12: 8 | B12: Presentación final | C12: =SUM('Historias de Usuario'!G88:G90) -> 24
A13: Total | C13: =SUM(C5:C12) -> 324
A15: Horas consumidas (reconstrucción)
A16: No existe un registro diario de horas. Se reconstruyeron a partir de lo informado por el equipo: una dedicación al proyecto de unas 5 horas diarias por integrante. Solo se registran las horas de las tareas de desarrollo listadas en este archivo, con un máximo de 3 horas por día por integrante; el resto de la dedicación (reuniones, documentación, pruebas y aprendizaje) no está incluida. Las horas se repartieron entre las tareas ya realizadas de cada sprint, en el orden de la lista y según su dueño. En los sprints 3 y 5, donde el trabajo estimado de un integrante superaba ese máximo, las horas estimadas de esas tareas se ajustaron proporcionalmente. En el sprint 5 se registran todas las tareas terminadas hasta el 14/10/2026 (8 días hábiles); como su trabajo estimado superaba la capacidad de ese período, sus horas se ajustaron proporcionalmente, en tramos de media hora. Los sprints 6 a 8 no tienen horas consumidas porque aún no comienzan.
